Traceback (most recent call last):
  File "C:\Users\USER\miniconda3\envs\ml_tf\lib\site-packages\jupyter_cache\executors\utils.py", line 58, in single_nb_execution
    executenb(
  File "C:\Users\USER\miniconda3\envs\ml_tf\lib\site-packages\nbclient\client.py", line 1305, in execute
    return NotebookClient(nb=nb, resources=resources, km=km, **kwargs).execute()
  File "C:\Users\USER\miniconda3\envs\ml_tf\lib\site-packages\jupyter_core\utils\__init__.py", line 173, in wrapped
    return loop.run_until_complete(inner)
  File "C:\Users\USER\miniconda3\envs\ml_tf\lib\asyncio\base_events.py", line 647, in run_until_complete
    return future.result()
  File "C:\Users\USER\miniconda3\envs\ml_tf\lib\site-packages\nbclient\client.py", line 705, in async_execute
    await self.async_execute_cell(
  File "C:\Users\USER\miniconda3\envs\ml_tf\lib\site-packages\nbclient\client.py", line 1058, in async_execute_cell
    await self._check_raise_for_error(cell, cell_index, exec_reply)
  File "C:\Users\USER\miniconda3\envs\ml_tf\lib\site-packages\nbclient\client.py", line 914, in _check_raise_for_error
    raise CellExecutionError.from_cell_and_msg(cell, exec_reply_content)
nbclient.exceptions.CellExecutionError: An error occurred while executing the following cell:
------------------
try:
    connection = psycopg2.connect(user="undatascience-user",
                                  password="undatascience-password",
                                  host="localhost",
                                  port="5432",
                                  database="undatascience-db")

    cursor = connection.cursor()
    print("PostgreSQL server information")
    print(connection.get_dsn_parameters(), "\n")

    cursor.execute("SELECT version();")
    record = cursor.fetchone()
    print("You are connected to - ", record, "\n")

except (Exception, Error) as error:
    print("Error while connecting to PostgreSQL", error)
finally:
    if (connection):
        cursor.close()
        connection.close()
        print("PostgreSQL connection is closed")
------------------

----- stdout -----
Error while connecting to PostgreSQL connection to server at "localhost" (::1), port 5432 failed: Connection refused (0x0000274D/10061)
	Is the server running on that host and accepting TCP/IP connections?
connection to server at "localhost" (127.0.0.1), port 5432 failed: Connection refused (0x0000274D/10061)
	Is the server running on that host and accepting TCP/IP connections?
------------------

[1;31m---------------------------------------------------------------------------[0m
[1;31mNameError[0m                                 Traceback (most recent call last)
Cell [1;32mIn[2], line 19[0m
[0;32m     17[0m     [38;5;28mprint[39m([38;5;124m"[39m[38;5;124mError while connecting to PostgreSQL[39m[38;5;124m"[39m, error)
[0;32m     18[0m [38;5;28;01mfinally[39;00m:
[1;32m---> 19[0m     [38;5;28;01mif[39;00m ([43mconnection[49m):
[0;32m     20[0m         cursor[38;5;241m.[39mclose()
[0;32m     21[0m         connection[38;5;241m.[39mclose()

[1;31mNameError[0m: name 'connection' is not defined

